Workbook

Sheet Performance
B2: SWITCH · GOLF COURSE ROAD · MOBILE CALLING PERFORMANCE
B4: Live totals across every sector tab — updates as you fill the sheets
B6: TOTAL MOBILE LEADS | D6: CONTACTED | F6: ORDERS
B7: =COUNTA('Sector 26'!B5:B151)+COUNTA('Sector 27'!B5:B46)+COUNTA('Sector 28'!B5:B145)+COUNTA('Sector 42'!B5:B66)+COUNTA('Sector 43'!B5:B145)+COUNTA('Sector 44'!B5:B27)+COUNTA('Sector 45'!B5:B18)+COUNTA('Sector 50'!B5:B24)+COUNTA('Sector 52'!B5:B164)+COUNTA('Sector 53'!B5:B77)+COUNTA('Sector 54'!B5:B45)+COUNTA('Sector 55'!B5:B40)+COUNTA('Sector 56'!B5:B109)+COUNTA('Sector 57'!B5:B88)+COUNTA('Sector 58'!B5:B46)+COUNTA('Sector 59'!B5:B22)+COUNTA('Sector 60'!B5:B15)+COUNTA('Sector 61'!B5:B38)+COUNTA('Sector 62'!B5:B92)+COUNTA('Sector 63'!B5:B21)+COUNTA('Sector 64'!B5:B56)+COUNTA('Sector 65'!B5:B128)+COUNTA('Sector 66'!B5:B94)+COUNTA('Sector 67'!B5:B66)+COUNTA('GCR — Other'!B5:B22) | D7: =COUNTA('Sector 26'!I5:I151)+COUNTA('Sector 27'!I5:I46)+COUNTA('Sector 28'!I5:I145)+COUNTA('Sector 42'!I5:I66)+COUNTA('Sector 43'!I5:I145)+COUNTA('Sector 44'!I5:I27)+COUNTA('Sector 45'!I5:I18)+COUNTA('Sector 50'!I5:I24)+COUNTA('Sector 52'!I5:I164)+COUNTA('Sector 53'!I5:I77)+COUNTA('Sector 54'!I5:I45)+COUNTA('Sector 55'!I5:I40)+COUNTA('Sector 56'!I5:I109)+COUNTA('Sector 57'!I5:I88)+COUNTA('Sector 58'!I5:I46)+COUNTA('Sector 59'!I5:I22)+COUNTA('Sector 60'!I5:I15)+COUNTA('Sector 61'!I5:I38)+COUNTA('Sector 62'!I5:I92)+COUNTA('Sector 63'!I5:I21)+COUNTA('Sector 64'!I5:I56)+COUNTA('Sector 65'!I5:I128)+COUNTA('Sector 66'!I5:I94)+COUNTA('Sector 67'!I5:I66)+COUNTA('GCR — Other'!I5:I22) | F7: =COUNTIF('Sector 26'!K5:K151,"Yes")+COUNTIF('Sector 27'!K5:K46,"Yes")+COUNTIF('Sector 28'!K5:K145,"Yes")+COUNTIF('Sector 42'!K5:K66,"Yes")+COUNTIF('Sector 43'!K5:K145,"Yes")+COUNTIF('Sector 44'!K5:K27,"Yes")+COUNTIF('Sector 45'!K5:K18,"Yes")+COUNTIF('Sector 50'!K5:K24,"Yes")+COUNTIF('Sector 52'!K5:K164,"Yes")+COUNTIF('Sector 53'!K5:K77,"Yes")+COUNTIF('Sector 54'!K5:K45,"Yes")+COUNTIF('Sector 55'!K5:K40,"Yes")+COUNTIF('Sector 56'!K5:K109,"Yes")+COUNTIF('Sector 57'!K5:K88,"Yes")+COUNTIF('Sector 58'!K5:K46,"Yes")+COUNTIF('Sector 59'!K5:K22,"Yes")+COUNTIF('Sector 60'!K5:K15,"Yes")+COUNTIF('Sector 61'!K5:K38,"Yes")+COUNTIF('Sector 62'!K5:K92,"Yes")+COUNTIF('Sector 63'!K5:K21,"Yes")+COUNTIF('Sector 64'!K5:K56,"Yes")+COUNTIF('Sector 65'!K5:K128,"Yes")+COUNTIF('Sector 66'!K5:K94,"Yes")+COUNTIF('Sector 67'!K5:K66,"Yes")+COUNTIF('GCR — Other'!K5:K22,"Yes")
B9: INTERESTED | D9: CONVERSION | F9: HOURS BOOKED
B10: =COUNTIF('Sector 26'!I5:I151,"Yes")+COUNTIF('Sector 27'!I5:I46,"Yes")+COUNTIF('Sector 28'!I5:I145,"Yes")+COUNTIF('Sector 42'!I5:I66,"Yes")+COUNTIF('Sector 43'!I5:I145,"Yes")+COUNTIF('Sector 44'!I5:I27,"Yes")+COUNTIF('Sector 45'!I5:I18,"Yes")+COUNTIF('Sector 50'!I5:I24,"Yes")+COUNTIF('Sector 52'!I5:I164,"Yes")+COUNTIF('Sector 53'!I5:I77,"Yes")+COUNTIF('Sector 54'!I5:I45,"Yes")+COUNTIF('Sector 55'!I5:I40,"Yes")+COUNTIF('Sector 56'!I5:I109,"Yes")+COUNTIF('Sector 57'!I5:I88,"Yes")+COUNTIF('Sector 58'!I5:I46,"Yes")+COUNTIF('Sector 59'!I5:I22,"Yes")+COUNTIF('Sector 60'!I5:I15,"Yes")+COUNTIF('Sector 61'!I5:I38,"Yes")+COUNTIF('Sector 62'!I5:I92,"Yes")+COUNTIF('Sector 63'!I5:I21,"Yes")+COUNTIF('Sector 64'!I5:I56,"Yes")+COUNTIF('Sector 65'!I5:I128,"Yes")+COUNTIF('Sector 66'!I5:I94,"Yes")+COUNTIF('Sector 67'!I5:I66,"Yes")+COUNTIF('GCR — Other'!I5:I22,"Yes") | D10: =IFERROR((COUNTIF('Sector 26'!K5:K151,"Yes")+COUNTIF('Sector 27'!K5:K46,"Yes")+COUNTIF('Sector 28'!K5:K145,"Yes")+COUNTIF('Sector 42'!K5:K66,"Yes")+COUNTIF('Sector 43'!K5:K145,"Yes")+COUNTIF('Sector 44'!K5:K27,"Yes")+COUNTIF('Sector 45'!K5:K18,"Yes")+COUNTIF('Sector 50'!K5:K24,"Yes")+COUNTIF('Sector 52'!K5:K164,"Yes")+COUNTIF('Sector 53'!K5:K77,"Yes")+COUNTIF('Sector 54'!K5:K45,"Yes")+COUNTIF('Sector 55'!K5:K40,"Yes")+COUNTIF('Sector 56'!K5:K109,"Yes")+COUNTIF('Sector 57'!K5:K88,"Yes")+COUNTIF('Sector 58'!K5:K46,"Yes")+COUNTIF('Sector 59'!K5:K22,"Yes")+COUNTIF('Sector 60'!K5:K15,"Yes")+COUNTIF('Sector 61'!K5:K38,"Yes")+COUNTIF('Sector 62'!K5:K92,"Yes")+COUNTIF('Sector 63'!K5:K21,"Yes")+COUNTIF('Sector 64'!K5:K56,"Yes")+COUNTIF('Sector 65'!K5:K128,"Yes")+COUNTIF('Sector 66'!K5:K94,"Yes")+COUNTIF('Sector 67'!K5:K66,"Yes")+COUNTIF('GCR — Other'!K5:K22,"Yes"))/(COUNTA('Sector 26'!I5:I151)+COUNTA('Sector 27'!I5:I46)+COUNTA('Sector 28'!I5:I145)+COUNTA('Sector 42'!I5:I66)+COUNTA('Sector 43'!I5:I145)+COUNTA('Sector 44'!I5:I27)+COUNTA('Sector 45'!I5:I18)+COUNTA('Sector 50'!I5:I24)+COUNTA('Sector 52'!I5:I164)+COUNTA('Sector 53'!I5:I77)+COUNTA('Sector 54'!I5:I45)+COUNTA('Sector 55'!I5:I40)+COUNTA('Sector 56'!I5:I109)+COUNTA('Sector 57'!I5:I88)+COUNTA('Sector 58'!I5:I46)+COUNTA('Sector 59'!I5:I22)+COUNTA('Sector 60'!I5:I15)+COUNTA('Sector 61'!I5:I38)+COUNTA('Sector 62'!I5:I92)+COUNTA('Sector 63'!I5:I21)+COUNTA('Sector 64'!I5:I56)+COUNTA('Sector 65'!I5:I128)+COUNTA('Sector 66'!I5:I94)+COUNTA('Sector 67'!I5:I66)+COUNTA('GCR — Other'!I5:I22)),0) | F10: =SUM('Sector 26'!J5:J151)+SUM('Sector 27'!J5:J46)+SUM('Sector 28'!J5:J145)+SUM('Sector 42'!J5:J66)+SUM('Sector 43'!J5:J145)+SUM('Sector 44'!J5:J27)+SUM('Sector 45'!J5:J18)+SUM('Sector 50'!J5:J24)+SUM('Sector 52'!J5:J164)+SUM('Sector 53'!J5:J77)+SUM('Sector 54'!J5:J45)+SUM('Sector 55'!J5:J40)+SUM('Sector 56'!J5:J109)+SUM('Sector 57'!J5:J88)+SUM('Sector 58'!J5:J46)+SUM('Sector 59'!J5:J22)+SUM('Sector 60'!J5:J15)+SUM('Sector 61'!J5:J38)+SUM('Sector 62'!J5:J92)+SUM('Sector 63'!J5:J21)+SUM('Sector 64'!J5:J56)+SUM('Sector 65'!J5:J128)+SUM('Sector 66'!J5:J94)+SUM('Sector 67'!J5:J66)+SUM('GCR — Other'!J5:J22)
B12: Sector | C12: Leads | D12: Contacted | E12: Interested | F12: Orders | G12: Hours
B13: Sector 26 | C13: =COUNTA('Sector 26'!B5:B151) | D13: =COUNTA('Sector 26'!I5:I151) | E13: =COUNTIF('Sector 26'!I5:I151,"Yes") | F13: =COUNTIF('Sector 26'!K5:K151,"Yes") | G13: =SUM('Sector 26'!J5:J151)
B14: Sector 27 | C14: =COUNTA('Sector 27'!B5:B46) | D14: =COUNTA('Sector 27'!I5:I46) | E14: =COUNTIF('Sector 27'!I5:I46,"Yes") | F14: =COUNTIF('Sector 27'!K5:K46,"Yes") | G14: =SUM('Sector 27'!J5:J46)
B15: Sector 28 | C15: =COUNTA('Sector 28'!B5:B145) | D15: =COUNTA('Sector 28'!I5:I145) | E15: =COUNTIF('Sector 28'!I5:I145,"Yes") | F15: =COUNTIF('Sector 28'!K5:K145,"Yes") | G15: =SUM('Sector 28'!J5:J145)
B16: Sector 42 | C16: =COUNTA('Sector 42'!B5:B66) | D16: =COUNTA('Sector 42'!I5:I66) | E16: =COUNTIF('Sector 42'!I5:I66,"Yes") | F16: =COUNTIF('Sector 42'!K5:K66,"Yes") | G16: =SUM('Sector 42'!J5:J66)
B17: Sector 43 | C17: =COUNTA('Sector 43'!B5:B145) | D17: =COUNTA('Sector 43'!I5:I145) | E17: =COUNTIF('Sector 43'!I5:I145,"Yes") | F17: =COUNTIF('Sector 43'!K5:K145,"Yes") | G17: =SUM('Sector 43'!J5:J145)
B18: Sector 44 | C18: =COUNTA('Sector 44'!B5:B27) | D18: =COUNTA('Sector 44'!I5:I27) | E18: =COUNTIF('Sector 44'!I5:I27,"Yes") | F18: =COUNTIF('Sector 44'!K5:K27,"Yes") | G18: =SUM('Sector 44'!J5:J27)
B19: Sector 45 | C19: =COUNTA('Sector 45'!B5:B18) | D19: =COUNTA('Sector 45'!I5:I18) | E19: =COUNTIF('Sector 45'!I5:I18,"Yes") | F19: =COUNTIF('Sector 45'!K5:K18,"Yes") | G19: =SUM('Sector 45'!J5:J18)
B20: Sector 50 | C20: =COUNTA('Sector 50'!B5:B24) | D20: =COUNTA('Sector 50'!I5:I24) | E20: =COUNTIF('Sector 50'!I5:I24,"Yes") | F20: =COUNTIF('Sector 50'!K5:K24,"Yes") | G20: =SUM('Sector 50'!J5:J24)
B21: Sector 52 | C21: =COUNTA('Sector 52'!B5:B164) | D21: =COUNTA('Sector 52'!I5:I164) | E21: =COUNTIF('Sector 52'!I5:I164,"Yes") | F21: =COUNTIF('Sector 52'!K5:K164,"Yes") | G21: =SUM('Sector 52'!J5:J164)
B22: Sector 53 | C22: =COUNTA('Sector 53'!B5:B77) | D22: =COUNTA('Sector 53'!I5:I77) | E22: =COUNTIF('Sector 53'!I5:I77,"Yes") | F22: =COUNTIF('Sector 53'!K5:K77,"Yes") | G22: =SUM('Sector 53'!J5:J77)
B23: Sector 54 | C23: =COUNTA('Sector 54'!B5:B45) | D23: =COUNTA('Sector 54'!I5:I45) | E23: =COUNTIF('Sector 54'!I5:I45,"Yes") | F23: =COUNTIF('Sector 54'!K5:K45,"Yes") | G23: =SUM('Sector 54'!J5:J45)
B24: Sector 55 | C24: =COUNTA('Sector 55'!B5:B40) | D24: =COUNTA('Sector 55'!I5:I40) | E24: =COUNTIF('Sector 55'!I5:I40,"Yes") | F24: =COUNTIF('Sector 55'!K5:K40,"Yes") | G24: =SUM('Sector 55'!J5:J40)
B25: Sector 56 | C25: =COUNTA('Sector 56'!B5:B109) | D25: =COUNTA('Sector 56'!I5:I109) | E25: =COUNTIF('Sector 56'!I5:I109,"Yes") | F25: =COUNTIF('Sector 56'!K5:K109,"Yes") | G25: =SUM('Sector 56'!J5:J109)
B26: Sector 57 | C26: =COUNTA('Sector 57'!B5:B88) | D26: =COUNTA('Sector 57'!I5:I88) | E26: =COUNTIF('Sector 57'!I5:I88,"Yes") | F26: =COUNTIF('Sector 57'!K5:K88,"Yes") | G26: =SUM('Sector 57'!J5:J88)
B27: Sector 58 | C27: =COUNTA('Sector 58'!B5:B46) | D27: =COUNTA('Sector 58'!I5:I46) | E27: =COUNTIF('Sector 58'!I5:I46,"Yes") | F27: =COUNTIF('Sector 58'!K5:K46,"Yes") | G27: =SUM('Sector 58'!J5:J46)
B28: Sector 59 | C28: =COUNTA('Sector 59'!B5:B22) | D28: =COUNTA('Sector 59'!I5:I22) | E28: =COUNTIF('Sector 59'!I5:I22,"Yes") | F28: =COUNTIF('Sector 59'!K5:K22,"Yes") | G28: =SUM('Sector 59'!J5:J22)
B29: Sector 60 | C29: =COUNTA('Sector 60'!B5:B15) | D29: =COUNTA('Sector 60'!I5:I15) | E29: =COUNTIF('Sector 60'!I5:I15,"Yes") | F29: =COUNTIF('Sector 60'!K5:K15,"Yes") | G29: =SUM('Sector 60'!J5:J15)
B30: Sector 61 | C30: =COUNTA('Sector 61'!B5:B38) | D30: =COUNTA('Sector 61'!I5:I38) | E30: =COUNTIF('Sector 61'!I5:I38,"Yes") | F30: =COUNTIF('Sector 61'!K5:K38,"Yes") | G30: =SUM('Sector 61'!J5:J38)
B31: Sector 62 | C31: =COUNTA('Sector 62'!B5:B92) | D31: =COUNTA('Sector 62'!I5:I92) | E31: =COUNTIF('Sector 62'!I5:I92,"Yes") | F31: =COUNTIF('Sector 62'!K5:K92,"Yes") | G31: =SUM('Sector 62'!J5:J92)
B32: Sector 63 | C32: =COUNTA('Sector 63'!B5:B21) | D32: =COUNTA('Sector 63'!I5:I21) | E32: =COUNTIF('Sector 63'!I5:I21,"Yes") | F32: =COUNTIF('Sector 63'!K5:K21,"Yes") | G32: =SUM('Sector 63'!J5:J21)
B33: Sector 64 | C33: =COUNTA('Sector 64'!B5:B56) | D33: =COUNTA('Sector 64'!I5:I56) | E33: =COUNTIF('Sector 64'!I5:I56,"Yes") | F33: =COUNTIF('Sector 64'!K5:K56,"Yes") | G33: =SUM('Sector 64'!J5:J56)
B34: Sector 65 | C34: =COUNTA('Sector 65'!B5:B128) | D34: =COUNTA('Sector 65'!I5:I128) | E34: =COUNTIF('Sector 65'!I5:I128,"Yes") | F34: =COUNTIF('Sector 65'!K5:K128,"Yes") | G34: =SUM('Sector 65'!J5:J128)
B35: Sector 66 | C35: =COUNTA('Sector 66'!B5:B94) | D35: =COUNTA('Sector 66'!I5:I94) | E35: =COUNTIF('Sector 66'!I5:I94,"Yes") | F35: =COUNTIF('Sector 66'!K5:K94,"Yes") | G35: =SUM('Sector 66'!J5:J94)
B36: Sector 67 | C36: =COUNTA('Sector 67'!B5:B66) | D36: =COUNTA('Sector 67'!I5:I66) | E36: =COUNTIF('Sector 67'!I5:I66,"Yes") | F36: =COUNTIF('Sector 67'!K5:K66,"Yes") | G36: =SUM('Sector 67'!J5:J66)
B37: GCR — Other | C37: =COUNTA('GCR — Other'!B5:B22) | D37: =COUNTA('GCR — Other'!I5:I22) | E37: =COUNTIF('GCR — Other'!I5:I22,"Yes") | F37: =COUNTIF('GCR — Other'!K5:K22,"Yes") | G37: =SUM('GCR — Other'!J5:J22)
B38: TOTAL | C38: =COUNTA('Sector 26'!B5:B151)+COUNTA('Sector 27'!B5:B46)+COUNTA('Sector 28'!B5:B145)+COUNTA('Sector 42'!B5:B66)+COUNTA('Sector 43'!B5:B145)+COUNTA('Sector 44'!B5:B27)+COUNTA('Sector 45'!B5:B18)+COUNTA('Sector 50'!B5:B24)+COUNTA('Sector 52'!B5:B164)+COUNTA('Sector 53'!B5:B77)+COUNTA('Sector 54'!B5:B45)+COUNTA('Sector 55'!B5:B40)+COUNTA('Sector 56'!B5:B109)+COUNTA('Sector 57'!B5:B88)+COUNTA('Sector 58'!B5:B46)+COUNTA('Sector 59'!B5:B22)+COUNTA('Sector 60'!B5:B15)+COUNTA('Sector 61'!B5:B38)+COUNTA('Sector 62'!B5:B92)+COUNTA('Sector 63'!B5:B21)+COUNTA('Sector 64'!B5:B56)+COUNTA('Sector 65'!B5:B128)+COUNTA('Sector 66'!B5:B94)+COUNTA('Sector 67'!B5:B66)+COUNTA('GCR — Other'!B5:B22) | D38: =COUNTA('Sector 26'!I5:I151)+COUNTA('Sector 27'!I5:I46)+COUNTA('Sector 28'!I5:I145)+COUNTA('Sector 42'!I5:I66)+COUNTA('Sector 43'!I5:I145)+COUNTA('Sector 44'!I5:I27)+COUNTA('Sector 45'!I5:I18)+COUNTA('Sector 50'!I5:I24)+COUNTA('Sector 52'!I5:I164)+COUNTA('Sector 53'!I5:I77)+COUNTA('Sector 54'!I5:I45)+COUNTA('Sector 55'!I5:I40)+COUNTA('Sector 56'!I5:I109)+COUNTA('Sector 57'!I5:I88)+COUNTA('Sector 58'!I5:I46)+COUNTA('Sector 59'!I5:I22)+COUNTA('Sector 60'!I5:I15)+COUNTA('Sector 61'!I5:I38)+COUNTA('Sector 62'!I5:I92)+COUNTA('Sector 63'!I5:I21)+COUNTA('Sector 64'!I5:I56)+COUNTA('Sector 65'!I5:I128)+COUNTA('Sector 66'!I5:I94)+COUNTA('Sector 67'!I5:I66)+COUNTA('GCR — Other'!I5:I22) | E38: =COUNTIF('Sector 26'!I5:I151,"Yes")+COUNTIF('Sector 27'!I5:I46,"Yes")+COUNTIF('Sector 28'!I5:I145,"Yes")+COUNTIF('Sector 42'!I5:I66,"Yes")+COUNTIF('Sector 43'!I5:I145,"Yes")+COUNTIF('Sector 44'!I5:I27,"Yes")+COUNTIF('Sector 45'!I5:I18,"Yes")+COUNTIF('Sector 50'!I5:I24,"Yes")+COUNTIF('Sector 52'!I5:I164,"Yes")+COUNTIF('Sector 53'!I5:I77,"Yes")+COUNTIF('Sector 54'!I5:I45,"Yes")+COUNTIF('Sector 55'!I5:I40,"Yes")+COUNTIF('Sector 56'!I5:I109,"Yes")+COUNTIF('Sector 57'!I5:I88,"Yes")+COUNTIF('Sector 58'!I5:I46,"Yes")+COUNTIF('Sector 59'!I5:I22,"Yes")+COUNTIF('Sector 60'!I5:I15,"Yes")+COUNTIF('Sector 61'!I5:I38,"Yes")+COUNTIF('Sector 62'!I5:I92,"Yes")+COUNTIF('Sector 63'!I5:I21,"Yes")+COUNTIF('Sector 64'!I5:I56,"Yes")+COUNTIF('Sector 65'!I5:I128,"Yes")+COUNTIF('Sector 66'!I5:I94,"Yes")+COUNTIF('Sector 67'!I5:I66,"Yes")+COUNTIF('GCR — Other'!I5:I22,"Yes") | F38: =COUNTIF('Sector 26'!K5:K151,"Yes")+COUNTIF('Sector 27'!K5:K46,"Yes")+COUNTIF('Sector 28'!K5:K145,"Yes")+COUNTIF('Sector 42'!K5:K66,"Yes")+COUNTIF('Sector 43'!K5:K145,"Yes")+COUNTIF('Sector 44'!K5:K27,"Yes")+COUNTIF('Sector 45'!K5:K18,"Yes")+COUNTIF('Sector 50'!K5:K24,"Yes")+COUNTIF('Sector 52'!K5:K164,"Yes")+COUNTIF('Sector 53'!K5:K77,"Yes")+COUNTIF('Sector 54'!K5:K45,"Yes")+COUNTIF('Sector 55'!K5:K40,"Yes")+COUNTIF('Sector 56'!K5:K109,"Yes")+COUNTIF('Sector 57'!K5:K88,"Yes")+COUNTIF('Sector 58'!K5:K46,"Yes")+COUNTIF('Sector 59'!K5:K22,"Yes")+COUNTIF('Sector 60'!K5:K15,"Yes")+COUNTIF('Sector 61'!K5:K38,"Yes")+COUNTIF('Sector 62'!K5:K92,"Yes")+COUNTIF('Sector 63'!K5:K21,"Yes")+COUNTIF('Sector 64'!K5:K56,"Yes")+COUNTIF('Sector 65'!K5:K128,"Yes")+COUNTIF('Sector 66'!K5:K94,"Yes")+COUNTIF('Sector 67'!K5:K66,"Yes")+COUNTIF('GCR — Other'!K5:K22,"Yes") | G38: =SUM('Sector 26'!J5:J151)+SUM('Sector 27'!J5:J46)+SUM('Sector 28'!J5:J145)+SUM('Sector 42'!J5:J66)+SUM('Sector 43'!J5:J145)+SUM('Sector 44'!J5:J27)+SUM('Sector 45'!J5:J18)+SUM('Sector 50'!J5:J24)+SUM('Sector 52'!J5:J164)+SUM('Sector 53'!J5:J77)+SUM('Sector 54'!J5:J45)+SUM('Sector 55'!J5:J40)+SUM('Sector 56'!J5:J109)+SUM('Sector 57'!J5:J88)+SUM('Sector 58'!J5:J46)+SUM('Sector 59'!J5:J22)+SUM('Sector 60'!J5:J15)+SUM('Sector 61'!J5:J38)+SUM('Sector 62'!J5:J92)+SUM('Sector 63'!J5:J21)+SUM('Sector 64'!J5:J56)+SUM('Sector 65'!J5:J128)+SUM('Sector 66'!J5:J94)+SUM('Sector 67'!J5:J66)+SUM('GCR — Other'!J5:J22)
B40: ↳ Fill Interested? / Hours / Order Confirmed? on each sector tab — these totals move automatically.

Sheet Cloud Kitchen Ops
A1: SWITCH · CLOUD KITCHEN OPERATORS · GO DIRECT (BULK STAFFING)
A2: Cloud kitchens barely list on Google — chase the OPERATORS instead. One facility runs 8–10 brands, so one contact = staff for many kitchens. Find their Gurgaon commissary (Sohna Rd / Udyog Vihar) and ask for the ops / kitchen manager.
A3: S.No | B3: Operator / Business | C3: Brands / what they run | D3: Suggested Roles (per shift) | E3: Where in Gurgaon | F3: Manager Mobile | G3: Interested? | H3: Hours (1-12) | I3: Order Confirmed? | J3: Remarks
A4: 1 | B4: Rebel Foods | C4: Faasos, Behrouz Biryani, Oven Story, Mojo Pizza, LunchBox, Sweet Truth | D4: Kitchen Helper, Cook, Packer, Delivery Rider, Dishwasher | E4: Sohna Rd / Udyog Vihar hubs | J4: 🔍 Research Gurgaon facility → ask for ops/kitchen manager
A5: 2 | B5: Kitchens@ (Swiggy) | C5: Swiggy's own multi-brand cloud-kitchen network | D5: Kitchen Helper, Cook, Packer, Dishwasher | E5: Multiple Gurgaon hubs | J5: 🔍 Research Gurgaon facility → ask for ops/kitchen manager
A6: 3 | B6: EatClub / Box8 | C6: Box8, MOJO Pizza, Itminaan Biryani, LEATS | D6: Kitchen Helper, Cook, Packer, Rider | E6: Sohna Rd / Sector 37 | J6: 🔍 Research Gurgaon facility → ask for ops/kitchen manager
A7: 4 | B7: Curefoods | C7: EatFit, CakeZone, Nomad Pizza, Sharief Bhai, Great Indian Khichdi | D7: Kitchen Helper, Cook, Packer, Dishwasher | E7: Gurgaon cloud hubs | J7: 🔍 Research Gurgaon facility → ask for ops/kitchen manager
A8: 5 | B8: Ghost Kitchens India | C8: Multi-brand ghost-kitchen facilities | D8: Kitchen Helper, Cook, Packer, Rider | E8: Gurgaon facilities | J8: 🔍 Research Gurgaon facility → ask for ops/kitchen manager
A9: 6 | B9: Loyal Hospitality | C9: Multi-brand cloud kitchens (Awadhi, Chinese, Punjabi...) | D9: Kitchen Helper, Cook, Packer | E9: Gurgaon hubs | J9: 🔍 Research Gurgaon facility → ask for ops/kitchen manager
A10: 7 | B10: Biryani By Kilo (BBK) | C10: BBK, Goila Butter Chicken, Ammi's Biryani | D10: Kitchen Helper, Cook, Packer, Rider | E10: Sohna Rd / Sector 39 | J10: 🔍 Research Gurgaon facility → ask for ops/kitchen manager
A11: 8 | B11: Wow! Momo Foods | C11: Wow! Momo, Wow! China, Wow! Chicken | D11: Kitchen Helper, Cook, Packer | E11: Gurgaon kitchen units | J11: 🔍 Research Gurgaon facility → ask for ops/kitchen manager
A12: 9 | B12: Chinese Wok | C12: Chinese Wok cloud outlets | D12: Kitchen Helper, Cook, Packer, Rider | E12: Multiple Gurgaon units | J12: 🔍 Research Gurgaon facility → ask for ops/kitchen manager
A13: 10 | B13: The Bowl Company / Bercos | C13: Bowl Co., Bercos cloud units | D13: Kitchen Helper, Cook, Dishwasher | E13: Gurgaon units | J13: 🔍 Research Gurgaon facility → ask for ops/kitchen manager
A14: ↓ Callable cloud kitchens found in the scrape (real mobiles) — call these now
A15: 1 | B15: Goila Butter Chicken | C15: north_indian_restaurant | D15: Kitchen Helper, Cook, Packer, Delivery Rider, Dishwasher | E15: H16/6, near Gurudwara, Block H, DLF Phase 1, Sector 26, Gurugram, Haryana 122002, India | F15: 8588887718 | J15: From Google scrape
A16: 2 | B16: Biryani Blues | C16: restaurant | D16: Kitchen Helper, Cook, Packer, Delivery Rider, Dishwasher | E16: Shop No A6, 3rd Floor, Mall, Ardee City, Sector 52, Gurugram, Haryana 122003, India | F16: 8010801000 | J16: From Google scrape
A17: 3 | B17: FreshMenu Gurgaon Sec 53 | C17: asian_restaurant | D17: Kitchen Helper, Cook, Packer, Delivery Rider, Dishwasher | E17: Saraswati Kunj, Parsvnath Exotica, DLF Phase 5, Sector 53, Gurugram, Haryana 122011, India | F17: 9513420082 | J17: From Google scrape
A18: 4 | B18: Mukku's Kitchen – Cloud Kitchen & Tiffin Service | C18: restaurant | D18: Kitchen Helper, Cook, Packer, Delivery Rider, Dishwasher | E18: F Block, Suncity, Sector 54, Gurugram, Haryana 122011, India | F18: 9584550787 | J18: From Google scrape
A19: 5 | B19: Charcoal Eats - Ramji Market | C19: restaurant | D19: Kitchen Helper, Cook, Packer, Delivery Rider, Dishwasher | E19: Triumph Hyundai Showroom Golf, Shop No. 17 On First Floor, Ramji Market Gramin Bank, Ullahawas, Sector 61, Gurugram, Haryana 122101, India | F19: 9022500500 | J19: From Google scrape

Sheet Sector 26
A1: SWITCH · SECTOR 26 · MOBILE CALL SHEET
A2: Owner/manager mobiles · shifts 1–12 hrs, pay after worker reports · instant replacement | 147 leads · 133 in priority industries (top)
A3: LEADS | B3: =COUNTA(B5:B151) | C3: CONTACTED | D3: =COUNTA(I5:I151) | E3: INTERESTED | F3: =COUNTIF(I5:I151,"Yes") | G3: ORDERS | H3: =COUNTIF(K5:K151,"Yes") | I3: HOURS BOOKED | J3: =SUM(J5:J151)
A4: S.No | B4: Business Name | C4: Target Industry | D4: Suggested Roles (per shift) | E4: Manager Mobile | F4: Rating | G4: Reviews | H4: Address | I4: Interested? | J4: Hours (1-12) | K4: Order Confirmed? | L4: Remarks | M4: Map
A5: 1 | B5: Sikandarpur Metro | C5: Warehouse / Logistics | D5: Loader, Packer, Picker, Warehouse Helper, Delivery | E5: 8510098048 | F5: 4.3 | G5: 2615 | H5: Metro Gaet, F3JV+3PX, Sikanderpur, DLF Phase 1, Sector 26, Gurugram, Haryana 122002, India | M5: Map
A6: 2 | B6: Cafe By Soul | Best Outdoor Cafe | C6: Restaurant / Food | D6: Kitchen Helper, Cook, Dishwasher, Waiter | E6: 8826856001 | F6: 4.2 | G6: 1283 | H6: B-11/1, Ashoka Cresent Marg, DLF Phase 1, Sector 26A, Gurugram, Haryana 122002, India | M6: Map
A7: 3 | B7: Truefitt & Hill - DLF Phase-1, Gurugram | C7: Restaurant / Food | D7: Kitchen Helper, Cook, Dishwasher, Waiter | E7: 9899694034 | F7: 4.8 | G7: 996 | H7: A-14/15, Golf Course Rd, DLF Phase 1, Sector 26A, Gurugram, Haryana 122002, India | M7: Map
A8: 4 | B8: RAASA Awadh, to your plate | C8: Restaurant / Food | D8: Kitchen Helper, Cook, Dishwasher, Waiter | E8: 8800791005 | F8: 4.7 | G8: 421 | H8: The shopping mall, C-117, Arjun Marg, Block E, DLF Phase 1, Sector 26A, Gurugram, Haryana 122002, India | M8: Map
A9: 5 | B9: Kith And Kin | C9: Shop / Retail | D9: Store Helper, Housekeeping, Security, Sales Staff | E9: 9599808613 | F9: 4.2 | G9: 402 | H9: Shopping Mall, Arjun Marg, Block E, DLF Phase 1, Sector 26, Gurugram, Haryana 122002, India | M9: Map
A10: 6 | B10: The Woodbury | C10: Hotel / OYO | D10: Housekeeping, Room Boy, Kitchen Helper, Front Desk | E10: 9999071320 | F10: 4.5 | G10: 308 | H10: 1, Kusum Marg, G Block, DLF Phase 1, Sector 26, Gurugram, Haryana 122002, India | M10: Map
A11: 7 | B11: Fabuliv Experience Centre | C11: Shop / Retail | D11: Store Helper, Housekeeping, Security, Sales Staff | E11: 7827133144 | F11: 4.3 | G11: 306 | H11: 3rd, Floor, A-14, 15, Golf Course Rd, DLF Phase 1, Sector 26A, Gurugram, Haryana 122002, India | M11: Map
A12: 8 | B12: Mughal Sarai | C12: Restaurant / Food | D12: Kitchen Helper, Cook, Dishwasher, Waiter | E12: 9710260786 | F12: 4 | G12: 206 | H12: Shopping Mall, D-144, Arjun Marg, DLF Phase 1, Sector 26A, Gurugram, Haryana 122002, India | M12: Map
A13: 9 | B13: Fun Station golf course road | C13: Restaurant / Food | D13: Kitchen Helper, Cook, Dishwasher, Waiter | E13: 9871864446 | F13: 3.9 | G13: 194 | H13: Golf Course Road, Block F4, 1, Block F, DLF Phase 1, Sector 26A, Gurugram, Haryana 122002, India | M13: Map
A14: 10 | B14: Dr Anuj Gaba - GABA HEALTH & WELLNESS | C14: Salon / Spa | D14: Ward Boy, Housekeeping, Attendant, Security | E14: 8287517670 | F14: 5 | G14: 165 | H14: Silver Oaks Apartments, 113-4C3, G Block, DLF Phase 1, Sector 26, Gurugram, Haryana 122002, India | M14: Map
A15: 11 | B15: Sailors Home - Gurgaon | C15: Hotel / OYO | D15: Housekeeping, Room Boy, Kitchen Helper, Front Desk | E15: 9711337992 | F15: 4.1 | G15: 165 | H15: 10/13, Block H, DLF Phase 1, Sector 26, Gurugram, Haryana 122002, India | M15: Map
A16: 12 | B16: Bed & Oats | C16: Hotel / OYO | D16: Office Boy, Housekeeping, Security, Helper | E16: 9773770290 | F16: 4.4 | G16: 153 | H16: 34, G - 19 Rd, G Block, DLF Phase 1, Sector 26, Gurugram, Haryana 122002, India | M16: Map
... A113: 109 | B113: New Laxmi Jewlers | C113: Shop / Retail | D113: Store Helper, Housekeeping, Security, Sales Staff | E113: 9268713758 | F113: 3 | G113: 1 | H113: Sikenderpur, Nambardar Market, Mehrauli-Gurgaon Rd, Block H, DLF Phase 1, Sector 26, Gurugram, Haryana 122002, India | M113: Map
A114: 110 | B114: Chamakandcharms | C114: Shop / Retail | D114: Store Helper, Housekeeping, Security, Sales Staff | E114: 8800381888 | H114: 19/2, G Block, DLF Phase 1, Sector 26, Gurugram, Haryana 122002, India | M114: Map
A115: 111 | B115: Complete Bathing Solution | C115: Shop / Retail | D115: Store Helper, Housekeeping, Security, Sales Staff | E115: 9211230134 | H115: A27/62, DLF Phase 1, Sector 26A, Gurugram, Haryana 122002, India | M115: Map
A116: 112 | B116: HealthnWellness by Dietician Rashmi | C116: Salon / Spa | D116: Ward Boy, Housekeeping, Attendant, Security | E116: 9811699251 | H116: Flat No. 002, Tower 2 The palms, South city, H-1 Rd, Block H, DLF Phase 1, Sector 26, Gurugram, Haryana 122009, India | M116: Map
A117: 113 | B117: Jabbar Steel Works | C117: Restaurant / Food | D117: Kitchen Helper, Cook, Dishwasher, Waiter | E117: 9810727485 | H117: Block H, DLF Phase 1, Sector 26, Gurugram, Haryana 122002, India | M117: Map
A118: 114 | B118: Jitendar Food | C118: Supermarket / Grocery | D118: Kitchen Helper, Cook, Dishwasher, Waiter | E118: 9599170373 | H118: 12, Jitendar Secator 29, DLF Phase 1, Sector 26, Gurugram, Haryana 122002, India | M118: Map
A119: 115 | B119: Kohler | C119: Shop / Retail | D119: Store Helper, Housekeeping, Security, Sales Staff | E119: 9810822617 | H119: 51, Ashoka Cresent Marg, DLF Phase 1, Sector 26A, Gurugram, Haryana 122002, India | M119: Map
A120: 116 | B120: Md Rafique Auto Mobile Service | C120: Warehouse / Logistics | D120: Office Boy, Housekeeping, Security, Helper | E120: 9870205277 | H120: U10/1, DLF, Block D, Sector 26A, Gurugram, Haryana 122002, India | M120: Map
A121: 117 | B121: Moving Box Packers And Movers Gurgaon | C121: Warehouse / Logistics | D121: Loader, Packer, Picker, Warehouse Helper, Delivery | E121: 8796995430 | H121: Shop No 17, Arjun Marg, Block E, DLF Phase 1, Sector 26A, Gurugram, Haryana 122002, India | M121: Map
A122: 118 | B122: NOONOO | C122: Shop / Retail | D122: Store Helper, Housekeeping, Security, Sales Staff | E122: 7678328764 | H122: M Square, 1, A-14 Ln, DLF Phase 1, Sector 26, Gurugram, Haryana 122002, India | M122: Map
A123: 119 | B123: Primary eye care | C123: Shop / Retail | D123: Store Helper, Housekeeping, Security, Sales Staff | E123: 9015812518 | H123: E4, QUTUB PLAZA, market, DLF Phase 1, Sector 26A, Gurugram, Haryana 122002, India | M123: Map
A124: 120 | B124: Purple Inn | C124: Hotel / OYO | D124: Housekeeping, Room Boy, Kitchen Helper, Front Desk | E124: 8088988711 | H124: F4H4+44X, Sikanderpur, Sector 26, Gurugram, Haryana 122002, India | M124: Map
A125: 121 | B125: Raunak Fast Food | C125: Restaurant / Food | D125: Kitchen Helper, Cook, Dishwasher, Waiter | E125: 7982786111 | H125: 5, DLF Phase 1, Sector 26, Gurugram, Haryana 122002, India | M125: Map
... A137: 133 | B137: Zain Chairs | C137: Shop / Retail | D137: Store Helper, Housekeeping, Security, Sales Staff | E137: 9873953786 | H137: 1, Kachnar Marg, Block H, DLF Phase 1, Sector 26, Haryana, Gurugram, Haryana 122002, India | M137: Map
A138: 134 | B138: Toothsi by MakeO | Invisible Braces & Aligners | DLF Phase 1 | C138: Other | D138: Ward Boy, Housekeeping, Attendant, Security | E138: 8451849771 | F138: 4.6 | G138: 294 | H138: No A, 14/1, Golf Course Rd, DLF Phase 1, Sector 26, Gurugram, Haryana 122002, India | M138: Map
A139: 135 | B139: Malik Tyre World | C139: Other | D139: Store Helper, Housekeeping, Security, Sales Staff | E139: 9278085708 | F139: 3.9 | G139: 252 | H139: Shop No. 1 & 2 Sikandarpur Rapid Metro Station, Opposite Metro Pillar No. 11, DLF Phase-1 Road, Block H, DLF Phase 1, Sector 26, Gurugram, Haryana 122002, India | M139: Map
A140: 136 | B140: Korec Physiocare - Dr. Debanjan Mondal and Dr. Soumyadip Bose | C140: Other | D140: Ward Boy, Housekeeping, Attendant, Security | E140: 9971806365 | F140: 5 | G140: 206 | H140: F 2/33A, DLF Phase:-1, DLF Phase 1, Sector 26A, Gurugram, Haryana 122021, India | M140: Map
A141: 137 | B141: Dr Lohiya Fracture Clinic | C141: Other | D141: Ward Boy, Housekeeping, Attendant, Security | E141: 9891054136 | F141: 4.7 | G141: 137 | H141: Opposite Govt middle school, sikanderpur ghosi, Mehrauli-Gurgaon Rd, Sikanderpur, Sector 26, Gurugram, Haryana 122002, India | M141: Map
A142: 138 | B142: Vaastu Sanjivanii | C142: Other | D142: Office Boy, Housekeeping, Security, Helper | E142: 9910558589 | F142: 4.9 | G142: 125 | H142: Block E, DLF Phase 1, Sector 26A, Gurugram, Haryana 122002, India | M142: Map
A143: 139 | B143: Balance pilates India | C143: Other | D143: Trainer, Housekeeping, Front Desk | E143: 9810105546 | F143: 4.8 | G143: 119 | H143: House No, 10, Ashoka Cresent Marg, DLF Phase 1, Sector 26A, Gurugram, Haryana 122002, India | M143: Map
A144: 140 | B144: Sachin Kakkar | C144: Other | D144: Trainer, Housekeeping, Front Desk | E144: 8586002020 | F144: 4.9 | G144: 109 | H144: B 1 /15, DLF Phase 1, Sector 26A, Gurugram, Haryana 122002, India | M144: Map
A145: 141 | B145: Dr. Mansi Bhayana - Homoeopathic physician | C145: Other | D145: Ward Boy, Housekeeping, Attendant, Security | E145: 9711191728 | F145: 5 | G145: 97 | H145: 14, Paschim Marg, DLF Phase 1, Sector 26A, Gurugram, Haryana 122002, India | M145: Map
A146: 142 | B146: 6/6 Eye Centre | Dr. Ashwani Aggarwal (MS - Ophthalmology, MBBS - Ophthalmologist/ Eye Surgeon) | Delhi Gurgaon | C146: Other | D146: Ward Boy, Housekeeping, Attendant, Security | E146: 9650286258 | F146: 4.4 | G146: 92 | H146: 74, Arjun Marg, Block E, DLF Phase 1, Sector 26A, Gurugram, Haryana 122002, India | M146: Map
A147: 143 | B147: Dr Sunil Marwah Clinic | C147: Other | D147: Ward Boy, Housekeeping, Attendant, Security | E147: 9810153207 | F147: 2.9 | G147: 80 | H147: F-1/9, DLF Phase-1, Block F, DLF Phase 1, Sector 26A, Gurugram, Haryana 122002, India | M147: Map
...

Sheet Sector 27
A1: SWITCH · SECTOR 27 · MOBILE CALL SHEET
A2: Owner/manager mobiles · shifts 1–12 hrs, pay after worker reports · instant replacement | 42 leads · 38 in priority industries (top)
A3: LEADS | B3: =COUNTA(B5:B46) | C3: CONTACTED | D3: =COUNTA(I5:I46) | E3: INTERESTED | F3: =COUNTIF(I5:I46,"Yes") | G3: ORDERS | H3: =COUNTIF(K5:K46,"Yes") | I3: HOURS BOOKED | J3: =SUM(J5:J46)
A4: S.No | B4: Business Name | C4: Target Industry | D4: Suggested Roles (per shift) | E4: Manager Mobile | F4: Rating | G4: Reviews | H4: Address | I4: Interested? | J4: Hours (1-12) | K4: Order Confirmed? | L4: Remarks | M4: Map
A5: 1 | B5: Karim's Sushant Lok - Original From Delhi 6 | C5: Restaurant / Food | D5: Kitchen Helper, Cook, Dishwasher, Waiter | E5: 9654902020 | F5: 4.8 | G5: 1222 | H5: B728, Santosh Plaza, Sushant Lok Phase I, Sector 27, Gurugram, Haryana 122002, India | M5: Map
A6: 2 | B6: PEHLE CHAI | C6: Restaurant / Food | D6: Kitchen Helper, Cook, Dishwasher, Waiter | E6: 7428908282 | F6: 4.3 | G6: 1100 | H6: PLOT NO 728, SHOP NO 1, GROUND FLOOR, SANTOSH PLAZA, 2 & 3, Sushant Lok Phase I, Sector 27, Gurugram, Haryana 122001, India | M6: Map
A7: 3 | B7: STEPiNN Ess Kay Ess Villa | C7: Hotel / OYO | D7: Housekeeping, Room Boy, Kitchen Helper, Front Desk | E7: 9971823335 | F7: 4.4 | G7: 440 | H7: F-13/13, DLF Phase 1, Sector 27, Gurugram, Haryana 122002, India | M7: Map
A8: 4 | B8: AKU'S - The Burger Co. | HQ27, Gurugram | C8: Restaurant / Food | D8: Kitchen Helper, Cook, Dishwasher, Waiter | E8: 9667519279 | F8: 4.8 | G8: 324 | H8: Showroom No 10, HQ27 - The Headquarters, B - 660, Sushant Lok Phase I, Sector 27, Gurugram, Haryana 122009, India | M8: Map
A9: 5 | B9: Varun Attri | Hair | Beauty | Unisex Salon in Gurugram | C9: Salon / Spa | D9: Beautician, Helper, Receptionist, Cleaner | E9: 8588857572 | F9: 4.6 | G9: 307 | H9: F-10/4, Golf Course Rd, DLF Phase 1, Sector 27, Gurugram, Haryana 122009, India | M9: Map
A10: 6 | B10: Dr Amit Bhasin | C10: Salon / Spa | D10: Office Boy, Housekeeping, Security, Helper | E10: 8527336665 | F10: 4.7 | G10: 254 | H10: Prive Skin Clinic, 6101, near Super Mart 1, DLF Phase IV, Sector 27, Gurugram, Haryana 122009, India | M10: Map
A11: 7 | B11: NOVY | C11: Restaurant / Food | D11: Kitchen Helper, Cook, Dishwasher, Waiter | E11: 9599711003 | F11: 4.6 | G11: 232 | H11: 8, HQ27 The Headquarters, Sector 27, Sector 43, Gurugram, Haryana 122009, India | M11: Map
A12: 8 | B12: Threads Physio | Best Physiotherapist in Gurgaon | Sports Physio & Rehab | ACL Surgery Specialist | C12: Salon / Spa | D12: Ward Boy, Housekeeping, Attendant, Security | E12: 9310138022 | F12: 4.8 | G12: 224 | H12: F, 10/4, Golf Course Rd, DLF Phase 1, Sector 27, Gurugram, Haryana 122001, India | M12: Map
A13: 9 | B13: PopnCrunch | C13: Restaurant / Food | D13: Kitchen Helper, Cook, Dishwasher, Waiter | E13: 9818050442 | F13: 4.9 | G13: 131 | H13: B 357A, Sushant Lok Rd, Sushant Lok Phase I, Sector 27, Gurugram, Haryana 122009, India | M13: Map
A14: 10 | B14: B One Premium Thai Spa Sector 27 DLF Phase 1 Gurugram | C14: Salon / Spa | D14: Beautician, Helper, Receptionist, Cleaner | E14: 8826788480 | F14: 4.8 | G14: 106 | H14: 2nd Floor, Rao Mohar Singh Complex, Golf Course Rd, DLF Phase 1, Sector 27, Gurugram, Haryana 122009, India | M14: Map
A15: 11 | B15: Plan B Luxe Spa | C15: Salon / Spa | D15: Beautician, Helper, Receptionist, Cleaner | E15: 9958043330 | F15: 4.7 | G15: 104 | H15: 1st Floor, Golf Course Rd, above 3M Care Servies On, DLF Phase 1, Sector 27, Gurugram, Haryana 122009, India | M15: Map
A16: 12 | B16: Say PC Enterprises | C16: Shop / Retail | D16: Store Helper, Housekeeping, Security, Sales Staff | E16: 9711111454 | F16: 4.9 | G16: 97 | H16: 121, near Community Centre DLF City Phase I., Sector 27, Gurugram, Haryana 122009, India | M16: Map
... A37: 33 | B37: Swaad Mahal Restaurant | C37: Restaurant / Food | D37: Kitchen Helper, Cook, Dishwasher, Waiter | E37: 8447038625 | F37: 5 | G37: 1 | H37: Block B, DLF Phase 1, Sector 27, Gurugram, Haryana 122009, India | M37: Map
A38: 34 | B38: Autoknox | C38: Shop / Retail | D38: Mechanic Helper, Cleaner, Washer | E38: 9873330036 | H38: opp. Arjun Marg, near Jalsa resturant, DLF Phase 1, Sector 27, Gurugram, Haryana 122009, India | M38: Map
A39: 35 | B39: Euna | C39: Shop / Retail | D39: Store Helper, Housekeeping, Security, Sales Staff | E39: 7464944944 | H39: 249, Sector 27, Gurugram, Haryana 122009, India | M39: Map
A40: 36 | B40: KOFFEE AND BEVV | C40: Restaurant / Food | D40: Kitchen Helper, Cook, Dishwasher, Waiter | E40: 9971870603 | H40: 6716, DLF Phase IV, Sector 27, Gurugram, Haryana 122009, India | M40: Map
A41: 37 | B41: Sri Bala Ji Gurgaon Taxi Services | C41: Warehouse / Logistics | D41: Office Boy, Housekeeping, Security, Helper | E41: 9660181898 | H41: 248, Sector 27, Gurugram, Haryana 122009, India | M41: Map
A42: 38 | B42: Unique Home Massage Spa | C42: Salon / Spa | D42: Beautician, Helper, Receptionist, Cleaner | E42: 7982517232 | H42: office no.1, A-92, Golf Course Rd, Sector 27, Gurugram, Haryana 122009, India | M42: Map
A43: 39 | B43: Nova IVF Fertility Center Gurugram - Best IVF Centre in Gurgaon, Haryana | C43: Other | D43: Office Boy, Housekeeping, Security, Helper | E43: 8044474652 | F43: 4.9 | G43: 213 | H43: Plot No 522, near Supermarket, Sector 27, Gurugram, Haryana 122009, India | M43: Map
A44: 40 | B44: Dr. Rashmi Agrawal | C44: Other | D44: Office Boy, Housekeeping, Security, Helper | E44: 9811775369 | F44: 5 | G44: 207 | H44: NOVA IVF, Plot No 522, Sector 27, Gurugram, Haryana 122009, India | M44: Map
A45: 41 | B45: eFiling Portal | C45: Other | D45: Office Boy, Housekeeping, Security, Helper | E45: 9555247000 | F45: 4.2 | G45: 125 | H45: 509 Sector 27, Sector 27, Gurugram, Haryana 122009, India | M45: Map
A46: 42 | B46: Sadhyog - Isha Hatha Yoga Center Gurgaon | C46: Other | D46: Trainer, Housekeeping, Front Desk | E46: 8178748463 | F46: 4.9 | G46: 93 | H46: Plot No. 489, Sector 27, Gurugram, Haryana 122009, India | M46: Map

Sheet Sector 28
A1: SWITCH · SECTOR 28 · MOBILE CALL SHEET
A2: Owner/manager mobiles · shifts 1–12 hrs, pay after worker reports · instant replacement | 141 leads · 127 in priority industries (top)
A3: LEADS | B3: =COUNTA(B5:B145) | C3: CONTACTED | D3: =COUNTA(I5:I145) | E3: INTERESTED | F3: =COUNTIF(I5:I145,"Yes") | G3: ORDERS | H3: =COUNTIF(K5:K145,"Yes") | I3: HOURS BOOKED | J3: =SUM(J5:J145)
A4: S.No | B4: Business Name | C4: Target Industry | D4: Suggested Roles (per shift) | E4: Manager Mobile | F4: Rating | G4: Reviews | H4: Address | I4: Interested? | J4: Hours (1-12) | K4: Order Confirmed? | L4: Remarks | M4: Map
A5: 1 | B5: Meena Bazaar | C5: Shop / Retail | D5: Store Helper, Housekeeping, Security, Sales Staff | E5: 7303888625 | F5: 4.9 | G5: 6996 | H5: A-1, Mehrauli-Gurgaon Rd, Sector 28, Sushant Lok Phase I, Gurugram, Haryana 122002, India | M5: Map
A6: 2 | B6: Haute24 | C6: Shop / Retail | D6: Store Helper, Housekeeping, Security, Sales Staff | E6: 9561794706 | F6: 4.2 | G6: 1670 | H6: 1314, 13th Ave Rd, near Galleria Market, Sector 28, DLF Phase IV, Gurugram, Haryana 122009, India | M6: Map
A7: 3 | B7: Hyundai Showroom, Dee Emm Hyundai - Sikanderpur, Near Sahara Mall, MG Road, Gurgaon | C7: Shop / Retail | D7: Store Helper, Housekeeping, Security, Sales Staff | E7: 9773647900 | F7: 4.9 | G7: 1373 | H7: Plot No. 90, Mehrauli-Gurgaon Rd, near Sahara Mall, Sector 28, DLF Phase 1, Gurugram, Haryana 122001, India | M7: Map
A8: 4 | B8: SURYANSH FAB GURUGRAM | C8: Shop / Retail | D8: Store Helper, Housekeeping, Security, Sales Staff | E8: 9810682621 | F8: 4.9 | G8: 1336 | H8: 103, 3/1, near GRAND MALL, Sector 28, DLF Phase 1, Gurugram, Haryana 122002, India | M8: Map
A9: 5 | B9: Floor & Furnishings, DLF | FF | C9: Shop / Retail | D9: Store Helper, Housekeeping, Security, Sales Staff | E9: 9643403802 | F9: 4.8 | G9: 1247 | H9: A-5, Mehrauli-Gurgaon Road, Mall Road, near Metro Pillar Number 94, Sector 28, DLF Phase 1, Gurugram, Haryana 122002, India | M9: Map
A10: 6 | B10: The Atara | C10: Hotel / OYO | D10: Housekeeping, Room Boy, Kitchen Helper, Front Desk | E10: 8527575333 | F10: 4.1 | G10: 628 | H10: A-29/10, behind Dt Mega Mall, Sector 28, DLF Phase 1, Gurugram, Haryana 122002, India | M10: Map
A11: 7 | B11: Jawa Yezdi BSA Motorcycles - Siddhanth Automobiles, MG Road, Gurugram | C11: Shop / Retail | D11: Store Helper, Housekeeping, Security, Sales Staff | E11: 8037537489 | F11: 4.8 | G11: 534 | H11: Metro Pillar 82 And 83, MG Road DLF Phase 1, nearby Jmd Regent Square, Sector 28, Arcade, Gurugram, Haryana 122002, India | M11: Map
A12: 8 | B12: Blue heaven therapy at Homes | C12: Salon / Spa | D12: Beautician, Helper, Receptionist, Cleaner | E12: 9382989566 | F12: 5 | G12: 470 | H12: Sector 28, Chakkarpur, Sector 43, Gurugram, Haryana 122009, India | M12: Map
A13: 9 | B13: ElectricOne Gurgaon DLF - Electric Vehicle Showroom | C13: Shop / Retail | D13: Office Boy, Housekeeping, Security, Helper | E13: 9811312988 | F13: 4.9 | G13: 450 | H13: Shop No 2, Mehrauli-Gurgaon Rd, opposite Pillar No P81, adjacent to Sahara Mall, Sector 28, DLF Phase 1, Gurugram, Haryana 122002, India | M13: Map
A14: 10 | B14: Barman Eye Care Center - Eye Specialist in Gurgaon | Cataract Specialist in Gurgaon | Ophthalmologist in Gurugram | C14: Restaurant / Food | D14: Kitchen Helper, Cook, Dishwasher, Waiter | E14: 9667888433 | F14: 4.8 | G14: 387 | H14: 4307, besides, Galleria Market, Sector 28, DLF Phase IV, Gurugram, Haryana 122009, India | M14: Map
A15: 11 | B15: Stately Suites MG Road | C15: Hotel / OYO | D15: Housekeeping, Room Boy, Kitchen Helper, Front Desk | E15: 9560078177 | F15: 4.1 | G15: 352 | H15: A151/A, Road, Sector 28, Sushant Lok Phase I, Gurugram, Haryana 122009, India | M15: Map
A16: 12 | B16: The Pink Falcon | C16: Restaurant / Food | D16: Office Boy, Housekeeping, Security, Helper | E16: 9315988586 | F16: 4.4 | G16: 328 | H16: Lower ground Floor, JMD Empire Square, Mehrauli-Gurgaon Rd, Sector 28, DLF Phase 1, Gurugram, Sikanderpur Ghosi, Haryana 122002, India | M16: Map
... A109: 105 | B109: S R Ledis Tailor | C109: Shop / Retail | D109: Store Helper, Housekeeping, Security, Sales Staff | E109: 8860429799 | F109: 1 | G109: 1 | H109: Shop No.4, Market, Jaina Market, Sector 28, Chakkarpur, Gurugram, Haryana 122002, India | M109: Map
A110: 106 | B110: Ambay Car Shingar | C110: Warehouse / Logistics | D110: Office Boy, Housekeeping, Security, Helper | E110: 9711597170 | H110: Shop Number 1, Old, Delhi Road, opp. Punjab National Bank, Sector 28, Sushant Lok Phase I, Gurugram, Haryana 122009, India | M110: Map
A111: 107 | B111: Anita Devi | C111: Shop / Retail | D111: Store Helper, Housekeeping, Security, Sales Staff | E111: 9693719840 | H111: Sector 28, Gurugram, Haryana 122002, India | M111: Map
A112: 108 | B112: Crazy Trader | C112: Shop / Retail | D112: Store Helper, Housekeeping, Security, Sales Staff | E112: 9582241693 | H112: 79, Mehrauli-Gurgaon Rd, Sector 28, Maruti Housing Colony, Sector 25, Gurugram, Haryana 122009, India | M112: Map
A113: 109 | B113: Deluxe Cargo Packers And Movers | C113: Warehouse / Logistics | D113: Loader, Packer, Picker, Warehouse Helper, Delivery | E113: 8796901998 | H113: Shop No, 433, Phase 1, Sector 28, Sushant Lok Phase I, Sector 43, Gurugram, Haryana 122009, India | M113: Map
A114: 110 | B114: Dev Shakya Tea Shop | C114: Shop / Retail | D114: Store Helper, Housekeeping, Security, Sales Staff | E114: 9528835702 | H114: 57, Mg Metro, Sector 28, DLF Phase 2, Sector 25, Gurugram, Haryana 122009, India | M114: Map
A115: 111 | B115: Devendra Kirana Store | C115: Supermarket / Grocery | D115: Store Helper, Housekeeping, Security, Sales Staff | E115: 7880214756 | H115: Devendra Aana Store, Sector 28, DLF City IV, Tikamgarh, Gurugram, Madhya Pradesh 122002, India | M115: Map
A116: 112 | B116: Gulab Footwear | C116: Shop / Retail | D116: Store Helper, Housekeeping, Security, Sales Staff | E116: 9958778828 | H116: A-46, 756, Vijay Cinema Hall Rd, Jaina Market, Sector 28, Chakkarpur, Gurugram, Haryana 122002, India | M116: Map
A117: 113 | B117: Himanshu General Store | C117: Restaurant / Food | D117: Store Helper, Housekeeping, Security, Sales Staff | E117: 9953077258 | H117: Himanshu General Store, near Dayal Public School, Sector 28, Chakkarpur, Gurugram, Haryana 122002, India | M117: Map
A118: 114 | B118: Jai Beauty Parlour | C118: Salon / Spa | D118: Beautician, Helper, Receptionist, Cleaner | E118: 8383051858 | H118: House No-16, 11A. Blocka, Balakishan Tower, Mg Road, Chakkarpur, Behind Sahara Mall, Gurugram, NCR, Sector 28, Chakkarpur, Region, Gurugram, Haryana 122002, India | M118: Map
A119: 115 | B119: Jai Krishan Fruits Shop | C119: Restaurant / Food | D119: Kitchen Helper, Cook, Dishwasher, Waiter | E119: 9289371197 | H119: Jaina Market, Sector 28, Chakkarpur, Gurugram, Haryana 122002, India | M119: Map
A120: 116 | B120: Laxman Readymade Garments | C120: Shop / Retail | D120: Store Helper, Housekeeping, Security, Sales Staff | E120: 8588888638 | H120: 761, near Jaina Mandir, Jaina Market, Sector 28, Chakkarpur, Gurugram, Haryana 122002, India | M120: Map
A121: 117 | B121: Leelsdhar Shop | C121: Shop / Retail | D121: Store Helper, Housekeeping, Security, Sales Staff | E121: 9024120859 | H121: 7, Sector 28, DLF Phase 2, Sector 24, Gurugram, Haryana 122009, India | M121: Map
... A131: 127 | B131: Yadav Fast Food | C131: Restaurant / Food | D131: Kitchen Helper, Cook, Dishwasher, Waiter | E131: 7739025853 | H131: Chakkarpur Village Rd, near by Radha Krishna Mandir, Sector 28, Chakkarpur, Gurugram, Haryana 122002, India | M131: Map
A132: 128 | B132: Universal Gym - Available on Cult.fit | Best gym in MG Road, Gurugram | C132: Other | D132: Trainer, Housekeeping, Front Desk | E132: 9911113032 | F132: 4.2 | G132: 319 | H132: Grace Rd 798 Saraswati Vihar, behind Sahara Mall, Sector 28, Chakkarpur, Gurugram, Haryana 122009, India | M132: Map
A133: 129 | B133: IB Global Academy - Best IB, IGCSE & SAT Tutor in Gurgaon | C133: Other | D133: Office Boy, Housekeeping, Security, Helper | E133: 9312411928 | F133: 4.9 | G133: 211 | H133: House No - 4315, 2nd Floor, near Galleria Market, Galleria Market, Sector 28, DLF Phase IV, Gurugram, Haryana 122009, India | M133: Map
A134: 130 | B134: DLF Heart Care Clinic | C134: Other | D134: Ward Boy, Housekeeping, Attendant, Security | E134: 9873214382 | F134: 4.3 | G134: 190 | H134: A- 41/27, DLF Phase 1, Sector 28, Chakkarpur, Gurugram, Haryana 122002, India | M134: Map
A135: 131 | B135: The Platform | C135: Other | D135: Trainer, Housekeeping, Front Desk | E135: 6371220920 | F135: 5 | G135: 136 | H135: V, 799, Grace Rd, Sector 28, Chakkarpur, Gurugram, Haryana 122009, India | M135: Map
A136: 132 | B136: astrology Vastu Numerology | C136: Other | D136: Office Boy, Housekeeping, Security, Helper | E136: 9653561556 | F136: 4.9 | G136: 121 | H136: 196 P, near Jan Pratinidhi Apartments, Sector 28, Chakkarpur, Gurugram, Haryana 122002, India | M136: Map
A137: 133 | B137: Dr. Dipika Thakur Physiotherapist - Physiotherapy Clinic Near Sector 42 & Sector 43 Gurgaon | C137: Other | D137: Ward Boy, Housekeeping, Attendant, Security | E137: 8800818568 | F137: 5 | G137: 97 | H137: Near, Supermart-1, Sector 28, DLF Phase IV, Gurugram, Haryana 122001, India | M137: Map
A138: 134 | B138: HW Infotech – Website & Mobile App Development | AI, Blockchain & SaaS Company | C138: Other | D138: Office Boy, Housekeeping, Security, Helper | E138: 7678430274 | F138: 5 | G138: 88 | H138: Cospaces Cowork Plot No 360, Golf Course Rd, Sector 28, Chakkarpur, Gurugram, Haryana 122002, India | M138: Map
A139: 135 | B139: Children First Mental Health Institute, Gurugram | C139: Other | D139: Ward Boy, Housekeeping, Attendant, Security | E139: 9650844774 | F139: 4.7 | G139: 78 | H139: B 18/9, Golf Course Rd, Sector 28, DLF Phase 1, Sector 26A, Gurugram, Haryana 122002, India | M139: Map
A140: 136 | B140: The Lifestyle Clinic: By Dr Jateen Ukrani & Dr Varsha Mahadik | C140: Other | D140: Ward Boy, Housekeeping, Attendant, Security | E140: 8368845563 | F140: 4.8 | G140: 76 | H140: H 1234 GF, sector 28, Maruti Vihar, Maruti Housing Colony, Gurgaonr, Gurugram, Haryana 122002, India | M140: Map
A141: 137 | B141: Dr. Ahtasham | C141: Other | D141: Ward Boy, Housekeeping, Attendant, Security | E141: 9205736607 | F141: 5 | G141: 62 | H141: 3410, near IVY APARTMENT, Sector 28, Sushant Lok Phase I, Sector 43, Gurugram, Haryana 122009, India | M141: Map
...

Sheet Sector 42
A1: SWITCH · SECTOR 42 · MOBILE CALL SHEET
A2: Owner/manager mobiles · shifts 1–12 hrs, pay after worker reports · instant replacement | 62 leads · 56 in priority industries (top)
A3: LEADS | B3: =COUNTA(B5:B66) | C3: CONTACTED | D3: =COUNTA(I5:I66) | E3: INTERESTED | F3: =COUNTIF(I5:I66,"Yes") | G3: ORDERS | H3: =COUNTIF(K5:K66,"Yes") | I3: HOURS BOOKED | J3: =SUM(J5:J66)
A4: S.No | B4: Business Name | C4: Target Industry | D4: Suggested Roles (per shift) | E4: Manager Mobile | F4: Rating | G4: Reviews | H4: Address | I4: Interested? | J4: Hours (1-12) | K4: Order Confirmed? | L4: Remarks | M4: Map
A5: 1 | B5: Mental Wellness Centre | C5: Salon / Spa | D5: Ward Boy, Housekeeping, Attendant, Security | E5: 9588392566 | F5: 4.8 | G5: 1047 | H5: First Floor, Plot No. 595, Golf Course Road, near Shiv Nadar Public School, Sector 42, Gurugram, Haryana 122009, India | M5: Map
A6: 2 | B6: Saltstayz Premier Sector 42 - Golf Course Road | C6: Hotel / OYO | D6: Housekeeping, Room Boy, Kitchen Helper, Front Desk | E6: 8800012701 | F6: 4.7 | G6: 951 | H6: Plot No. 780, Golf Crse Rd, Sector 42, Gurugram, Haryana 122009, India | M6: Map
A7: 3 | B7: Alaya Stays by ELIVAAS Eternal Oasis | C7: Hotel / OYO | D7: Office Boy, Housekeeping, Security, Helper | E7: 7969316141 | F7: 4.9 | G7: 425 | H7: Plot no. 591A, Sector 42, Gurugram, Haryana 122009, India | M7: Map
A8: 4 | B8: KOCA | C8: Restaurant / Food | D8: Kitchen Helper, Cook, Dishwasher, Waiter | E8: 8448184111 | F8: 4.4 | G8: 416 | H8: SCO4-7, Golf Avenue 42, Golf Course Rd, Sector 42, Gurugram, Haryana 122009, India | M8: Map
A9: 5 | B9: Effingut Brewpub Gurugram - India's most loved craft brew pub | C9: Restaurant / Food | D9: Office Boy, Housekeeping, Security, Helper | E9: 9211455592 | F9: 4.3 | G9: 403 | H9: 2nd Floor, Golf Avenue 42, Golf Course Rd, Sector 42, Gurugram, Haryana 122009, India | M9: Map
A10: 6 | B10: Eternal Oasis Gurugram | C10: Restaurant / Food | D10: Office Boy, Housekeeping, Security, Helper | E10: 7982883571 | F10: 4.5 | G10: 215 | H10: Landmark, Eternal Oasis, 591A, Sector 42 Main Rd, opposite Shiv Nadar School, Sector 42, Gurugram, Haryana 122002, India | M10: Map
A11: 7 | B11: Vaibhav Garg - Sports Performance Nutritionist & Metabolic Disorders Expert | C11: Salon / Spa | D11: Trainer, Housekeeping, Front Desk | E11: 9818467654 | F11: 4.9 | G11: 204 | H11: 697-P, Golf Course Rd, Sector 42, Gurugram, Haryana 122009, India | M11: Map
A12: 8 | B12: Diwan Saheb Gurugram | C12: Shop / Retail | D12: Store Helper, Housekeeping, Security, Sales Staff | E12: 8048070463 | F12: 4.2 | G12: 191 | H12: G 5-10, Ameya One Building Golf Course Road, Facing Rapid Metro Pillar No 91 Phase V, DLF Colony, Sector 42, Gurugram, Haryana 122011, India | M12: Map
A13: 9 | B13: Truefitt & Hill Ameya One | C13: Restaurant / Food | D13: Kitchen Helper, Cook, Dishwasher, Waiter | E13: 8527437773 | F13: 5 | G13: 158 | H13: Ameya One, Ground floor, Phase-5, Golf Course Rd, Sector 42, Gurugram, Haryana 122009, India | M13: Map
A14: 10 | B14: Cozy Stay (Co-living) Pg | C14: PG / Hostel | D14: Housekeeping, Cook, Caretaker, Security | E14: 9711181185 | F14: 4.7 | G14: 118 | H14: H.No 46C, near Cybercity and Ambience Mall, Sector 42, Gurugram, Haryana 122002, India | M14: Map
A15: 11 | B15: The Audio Co. | C15: Shop / Retail | D15: Store Helper, Housekeeping, Security, Sales Staff | E15: 9810502023 | F15: 5 | G15: 110 | H15: Plot 41, Sector 42, Gurugram, Haryana 122009, India | M15: Map
A16: 12 | B16: Needs Supermarket | C16: Supermarket / Grocery | D16: Store Helper, Housekeeping, Security, Sales Staff | E16: 9871211355 | F16: 4.1 | G16: 103 | H16: Tower 4, Magnolias Rd, Sector 42, Gurugram, Haryana 122009, India | M16: Map
... A58: 54 | B58: S K MOTERS | C58: Shop / Retail | D58: Mechanic Helper, Cleaner, Washer | E58: 6202881788 | F58: 4 | G58: 1 | H58: 371p, Sector 42, Gurugram, Haryana 122009, India | M58: Map
A59: 55 | B59: BMW Destination Charging Station | C59: Warehouse / Logistics | D59: Office Boy, Housekeeping, Security, Helper | E59: 8070743743 | H59: Magnolias Rd, Sector 42, Gurugram, Haryana 122009, India | M59: Map
A60: 56 | B60: Corumm | C60: Salon / Spa | D60: Beautician, Helper, Receptionist, Cleaner | E60: 9871614567 | H60: 3rd Floor, F-17/1, Golf Course Rd, DLF Phase 1, Sector 42, Gurugram, Haryana 122002, India | M60: Map
A61: 57 | B61: Preface Institute | C61: Other | D61: Peon, Housekeeping, Security, Attendant | E61: 9999488897 | F61: 5 | G61: 172 | H61: 525, J Near Camellias Apartments, Sector 42, Gurugram, Haryana 122002, India | M61: Map
A62: 58 | B62: Timeless Aesthetics | C62: Other | D62: Ward Boy, Housekeeping, Attendant, Security | E62: 9654009966 | F62: 4.8 | G62: 172 | H62: Ameya One, Sector 42, Gurugram, Haryana 122009, India | M62: Map
A63: 59 | B63: T and T Realty Services Pvt Ltd | C63: Other | D63: Office Boy, Housekeeping, Security, Helper | E63: 9873092255 | F63: 4.4 | G63: 154 | H63: second floor, Ameya One, Sector 42, Gurugram, Haryana 122009, India | M63: Map
A64: 60 | B64: Dr Guddi Kumari- best physiotherapist in gurgaon, cupping therapist, physiotherapy for home/neck pain/back pain/stroke/sports | C64: Other | D64: Ward Boy, Housekeeping, Attendant, Security | E64: 9818822205 | F64: 5 | G64: 114 | H64: White coat clinic, Plot no 372, off Golf Course Road, Sector 42, Gurugram, Haryana 122009, India | M64: Map
A65: 61 | B65: Mom's Preg-Ladder- Pregnancy, Birth & Beyond | C65: Other | D65: Office Boy, Housekeeping, Security, Helper | E65: 9711493909 | F65: 4.9 | G65: 104 | H65: Ground Floor, 697-P, Golf Crse Rd, Sector 42, Gurugram, Haryana 122009, India | M65: Map
A66: 62 | B66: Jagruti Rehab - Best Rehabilitation Centre & Mental Hospital in Gurgaon | Drug & Alcohol De-addiction Treatment | C66: Other | D66: Ward Boy, Housekeeping, Attendant, Security | E66: 9822207761 | F66: 4.4 | G66: 90 | H66: Plot no 596, Sector 42, Gurugram, Haryana 122009, India | M66: Map

Sheet Sector 43
A1: SWITCH · SECTOR 43 · MOBILE CALL SHEET
A2: Owner/manager mobiles · shifts 1–12 hrs, pay after worker reports · instant replacement | 141 leads · 127 in priority industries (top)
A3: LEADS | B3: =COUNTA(B5:B145) | C3: CONTACTED | D3: =COUNTA(I5:I145) | E3: INTERESTED | F3: =COUNTIF(I5:I145,"Yes") | G3: ORDERS | H3: =COUNTIF(K5:K145,"Yes") | I3: HOURS BOOKED | J3: =SUM(J5:J145)
A4: S.No | B4: Business Name | C4: Target Industry | D4: Suggested Roles (per shift) | E4: Manager Mobile | F4: Rating | G4: Reviews | H4: Address | I4: Interested? | J4: Hours (1-12) | K4: Order Confirmed? | L4: Remarks | M4: Map
A5: 1 | B5: Manhattan Bar & Brewery | C5: Restaurant / Food | D5: Kitchen Helper, Cook, Dishwasher, Waiter | E5: 8800697549 | F5: 4.4 | G5: 11223 | H5: 1st Floor Global Foyer Mall Unit 001, Golf Course Rd, Sector 43, Gurugram, Haryana 122009, India | M5: Map
A6: 2 | B6: Parul Garg | C6: Salon / Spa | D6: Office Boy, Housekeeping, Security, Helper | E6: 9599588312 | F6: 4.3 | G6: 1518 | H6: POWERGRID TOWNSHIP, D231, Gate, Sector 43, Gurugram, Haryana 122009, India | M6: Map
A7: 3 | B7: La La Land Brew Pub, Gurgaon | C7: Restaurant / Food | D7: Office Boy, Housekeeping, Security, Helper | E7: 8010950000 | F7: 4.3 | G7: 1484 | H7: 1st Floor, Global Foyer Mall, Golf Course Rd, Sector 43, Gurugram, Haryana 122009, India | M7: Map
A8: 4 | B8: ROF PORTICO | C8: Restaurant / Food | D8: Store Helper, Housekeeping, Security, Sales Staff | E8: 9999036154 | F8: 4.3 | G8: 859 | H8: I, Vyapar Kendra Rd, Sushant Lok, Block C, Sushant Lok Phase I, Sector 43, Gurugram, Haryana 122009, India | M8: Map
A9: 5 | B9: Limewood Signature - Huda City Centre | C9: Hotel / OYO | D9: Housekeeping, Room Boy, Kitchen Helper, Front Desk | E9: 9266591900 | F9: 4.9 | G9: 688 | H9: D-201 B, Sushant Lok Phase I, Sector 43, Gurugram, Haryana 122001, India | M9: Map
A10: 6 | B10: Quinnn Harper Unisex & Kids Salon | C10: Hotel / OYO | D10: Housekeeping, Room Boy, Kitchen Helper, Front Desk | E10: 8065076243 | F10: 4.8 | G10: 583 | H10: no 2, Market Gate, C 1001, near Vyapar Kendra Road, Block C, Sushant Lok Phase I, Sector 43, Gurugram, Haryana 122009, India | M10: Map
A11: 7 | B11: Cafe Dakia | C11: Restaurant / Food | D11: Kitchen Helper, Cook, Dishwasher, Waiter | E11: 8882006127 | F11: 4.5 | G11: 411 | H11: ROF PORTICO I, Vyapar Kendra Rd, Block C, Sushant Lok Phase I, Sector 43, Gurugram, Haryana 122009, India | M11: Map
A12: 8 | B12: Stretch Yog – Therapy & Wellness Center | C12: Salon / Spa | D12: Beautician, Helper, Receptionist, Cleaner | E12: 9529369361 | F12: 5 | G12: 323 | H12: Plot number 1183, near lord Krishna appartment, Block C, Sushant Lok Phase I, Sector 43, Gurugram, Haryana 122009, India | M12: Map
A13: 9 | B13: Golf Course Road Service Apartments | C13: Hotel / OYO | D13: Housekeeping, Room Boy, Kitchen Helper, Front Desk | E13: 7838881000 | F13: 4.7 | G13: 301 | H13: 1120, Golf Crse Rd, DLF Phase 5, Sector 43, Gurugram, Haryana 122009, India | M13: Map
A14: 10 | B14: Hotel B Stays | C14: Hotel / OYO | D14: Housekeeping, Room Boy, Kitchen Helper, Front Desk | E14: 9711721184 | F14: 4.8 | G14: 282 | H14: A-586, Block A, Sushant Lok Phase I, Sector 43, Gurugram, Haryana 122009, India | M14: Map
A15: 11 | B15: Shree Shyam Packers and Movers | Best Packers and Movers in Gurgaon | Packers and Movers Gurugram | C15: Warehouse / Logistics | D15: Loader, Packer, Picker, Warehouse Helper, Delivery | E15: 8708197926 | F15: 4.8 | G15: 256 | H15: Building Number - 680, C-BLOCK, Sector 43 Rd, Sushant Lok Phase I, Block C, Block B, Kanahi, Gurugram, Haryana 122009, India | M15: Map
A16: 12 | B16: Kiros Unisex Salon | C16: Salon / Spa | D16: Beautician, Helper, Receptionist, Cleaner | E16: 9899920150 | F16: 4.6 | G16: 251 | H16: Rof portico, Block C, Sushant Lok Phase I, Sector 43, Gurugram, Haryana 122009, India | M16: Map
... A121: 117 | B121: Sushiya Gurugram DLF 4 | C121: Restaurant / Food | D121: Kitchen Helper, Cook, Dishwasher, Waiter | E121: 9312444086 | F121: 1 | G121: 1 | H121: Shop 6, Khasra 505, Yadhuvanshi Market, Supermart 2, near DLF, Block C2, DLF Phase IV, Sector 43, Gurugram, Haryana 122002, India | M121: Map
A122: 118 | B122: ANNAPURNA RETAIL | C122: Supermarket / Grocery | D122: Store Helper, Housekeeping, Security, Sales Staff | E122: 8826282121 | H122: D 255, Sushant Lok Phase I, Sector 43, Gurugram, Haryana 122009, India | M122: Map
A123: 119 | B123: Bhaseer Ul Shop h | C123: Shop / Retail | D123: Store Helper, Housekeeping, Security, Sales Staff | E123: 8178985183 | H123: Shop Number 37, Horizon Colony, Sector 43, Gurugram, Haryana 122009, India | M123: Map
A124: 120 | B124: Dhaba Mithla Bhojan | C124: Restaurant / Food | D124: Kitchen Helper, Cook, Dishwasher, Waiter | E124: 9971606174 | H124: shop no . 3, plot, 7sp, Golf Course Rd, Sector 43, Gurugram, Haryana 122009, India | M124: Map
A125: 121 | B125: ElectricPe Charging Station | C125: Warehouse / Logistics | D125: Office Boy, Housekeeping, Security, Helper | E125: 8147060222 | H125: Sector43, Sector 41, Gurugram, Haryana 122015, India | M125: Map
A126: 122 | B126: Infinity Marketing Corporation | C126: Warehouse / Logistics | D126: Store Helper, Housekeeping, Security, Sales Staff | E126: 9899850105 | H126: House No.2962 First Floor, Block C, Sushant Lok Phase I, Sector 43, Gurugram, Haryana 122009, India | M126: Map
A127: 123 | B127: Mamajoyoga | C127: Hotel / OYO | D127: Beautician, Helper, Receptionist, Cleaner | E127: 9810766775 | H127: THE PINNACLE, Golf Course Rd, Horizon Colony, DLF Phase 5, Sector 43, Gurugram, Haryana 122009, India | M127: Map
A128: 124 | B128: Manoj Kumar | C128: Shop / Retail | D128: Store Helper, Housekeeping, Security, Sales Staff | E128: 7383679351 | H128: Olive Studio 1120, Golf Crse Rd, Sector 43, Gurugram, Haryana 122009, India | M128: Map
A129: 125 | B129: Speedex Packers And Movers Gurgaon | C129: Warehouse / Logistics | D129: Loader, Packer, Picker, Warehouse Helper, Delivery | E129: 8796965701 | H129: Shop No 16/D, Sector 43, Gurugram, Haryana 122009, India | M129: Map
A130: 126 | B130: Wheels of Freedom - Buy,Sell,Finance second hand bikes in Gurgaon | C130: Shop / Retail | D130: Store Helper, Housekeeping, Security, Sales Staff | E130: 7985611859 | H130: Opposite, Vyapar Kendra Rd, next to Indian oil petrol pump, Sushant Lok Phase I, Sector 43, Gurugram, Haryana 122009, India | M130: Map
A131: 127 | B131: Zee Jewels | C131: Shop / Retail | D131: Store Helper, Housekeeping, Security, Sales Staff | E131: 9599297140 | H131: Apartment, Sec-43, Hextax Commune, A 904, Sector 43, Gurugram, Haryana 122009, India | M131: Map
A132: 128 | B132: Super77 | C132: Other | D132: Office Boy, Housekeeping, Security, Helper | E132: 9557180240 | F132: 4.7 | G132: 1081 | H132: Human Charging India Pvt. Ltd, UTSAV-100, DLF Phase 5, Sector 43, Gurugram, Haryana 122009, India | M132: Map
A133: 129 | B133: OTWOGYMS | C133: Other | D133: Trainer, Housekeeping, Front Desk | E133: 9911243344 | F133: 4.3 | G133: 376 | H133: Shri Ram Complex, Block C, Sushant Lok Phase I, Sector 43, Gurugram, Haryana 122009, India | M133: Map
A134: 130 | B134: DOULA CLINIC - Best Lactation Consultant In Sector-43, Gurgaon | C134: Other | D134: Ward Boy, Housekeeping, Attendant, Security | E134: 7703969530 | F134: 4.9 | G134: 314 | H134: B-598 Ground Floor, Sushant Lok Phase I, Sector 43, Gurugram, Haryana 122009, India | M134: Map
A135: 131 | B135: Dietician Archana Batra's Clinic | C135: Other | D135: Ward Boy, Housekeeping, Attendant, Security | E135: 9971886474 | F135: 4.9 | G135: 300 | H135: House No. 97 (Lower Ground Floor, Power Grid Township Block-C2, Block C2, Sushant Lok Phase I, Sector 43, Gurugram, Haryana 122009, India | M135: Map
A136: 132 | B136: Grace IVF By Dr. Reubina Singh - IUI, ICSI, IVF Center In Gurgaon | Needle Free IVF In Gurgaon | C136: Other | D136: Ward Boy, Housekeeping, Attendant, Security | E136: 7558095116 | F136: 4.8 | G136: 224 | H136: 1327, Sector 43 Service Rd, Block C, PWO Appartments, Sector 43, Gurugram, Haryana 122009, India | M136: Map
A137: 133 | B137: EduGyani (Institutes and Home Tutors) | C137: Other | D137: Peon, Housekeeping, Security, Attendant | E137: 9315912518 | F137: 4.9 | G137: 221 | H137: C 359, Sushant Lok Phase I, Sector 43, Gurugram, Haryana 122002, India | M137: Map
A138: 134 | B138: Modenta Dental Clinic | C138: Other | D138: Ward Boy, Housekeeping, Attendant, Security | E138: 7837674763 | F138: 5 | G138: 220 | H138: 2772, St Thomas Marg, Block C, Sushant Lok Phase I, Sector 43, Gurugram, Haryana 122009, India | M138: Map
A139: 135 | B139: 𝐒𝐚𝐦𝐩𝐮𝐫𝐧 𝐕𝐚𝐬𝐭𝐮 | The Best Vastu Consultant in Gurgaon, India | C139: Other | D139: Office Boy, Housekeeping, Security, Helper | E139: 9625775679 | F139: 5 | G139: 210 | H139: Ground Floor, 567, Golf Course Rd, Sector 43, Gurugram, Haryana 122009, India | M139: Map
